Workbook

Sheet Lisez-moi
A1: RAPPROCHEMENT GRAND LIVRE -> P&L CONSOLIDE
A3: Source de verite : P&L par destination (onglet CB035-C). Le GL est par nature x entite.
A4: Le rapprochement porte sur les CHARGES + IS uniquement (le GL n'a pas de chiffre d'affaires).
A6: Onglets :
A7: Map_Entites : table de mapping entite GL -> entite P&L (traceur = Charges de personnel)
A8: Map_Postes : table de mapping poste GL -> ligne P&L (editable, recharger pour relancer)
A9: GL_source : grand livre parse + ligne P&L mappee par VLOOKUP (col H) = base tracable
A10: GL_retraite : GL agrege au format des lignes P&L, par entite (SUMIF sur GL_source)
A11: PnL_cible : valeurs cibles lues dans CB035-C
A12: Bridge_entite : GL recalcule vs P&L cible, ecart EUR et %, par entite
A13: Bridge_conso : bridge consolide (somme des 5 entites mappees)
A14: Ecarts : ecarts > seuil avec explication (MAPPING vs DONNEES)
... A17: KCOLD est l'entite ORPHELINE (aucune contrepartie P&L) : isolee, non incluse dans le consolide.

Sheet Map_Entites
A1: entite_GL | B1: entite_PnL | C1: justification (traceur Charges de personnel)
A2: H2R | B2: SARL H2R | C2: traceur personnel: -34944 vs -35546 (-1.7%)
A3: ALLIANCE | B3: SAS GROUPE RIVALIS | C3: traceur personnel: -252782 vs -238132 (6.2%) - seul appariement restant
A4: BM EST | B4: SARL BM EST | C4: traceur personnel: -2481037 vs -2516306 (-1.4%)
A5: KCOLD | B5: ORPHELIN | C5: aucune contrepartie P&L: 0 personnel, pas de CA, total -22057
A6: RIVAGROUPE | B6: RIVAGROUPE SAS | C6: traceur personnel: -219277 vs -221792 (-1.1%)
A7: VALPOLIS | B7: SARL VALPOLIS | C7: traceur personnel: -360393 vs -359684 (0.2%)

Sheet Map_Postes
A1: poste_GL | B1: ligne_PnL | C1: note
A2: Sous-traitance & prestations externes | B2: Charges externes
A3: Fournitures & petit équipement | B3: Achats consommés | C3: PCG: achats non stockés -> Achats consommés
A4: Énergie, eau & carburants | B4: Achats consommés | C4: PCG: achats non stockés -> Achats consommés
A5: Logiciels, IT & hébergement | B5: Charges externes
A6: Achats de marchandises | B6: Achats consommés
A7: Management fees / intra-groupe | B7: Opérations d'exploitation Intra-Groupe | C7: intra-groupe: net à 0 en consolidé
A8: Formation | B8: Charges externes
A9: Recrutement | B9: Charges externes
A10: Prestations conseillers TPE | B10: Charges externes
A11: Locations & crédit-bail | B11: Charges externes
A12: Entretien & maintenance | B12: Charges externes
A13: Assurances | B13: Charges externes
A14: Documentation & cotisations | B14: Charges externes
A15: Honoraires | B15: Charges externes
A16: Marketing & communication | B16: Charges externes
A17: Commissions sur encaissement | B17: Charges externes | C17: PCG: 622 -> Charges externes
A18: Déplacements, missions & réceptions | B18: Charges externes
A19: Frais postaux & télécom | B19: Charges externes
A20: Services bancaires | B20: Charges externes | C20: PCG: 627 -> Charges externes (non financier)
A21: Impôts & taxes d'exploitation | B21: Impôts et taxes
A22: Charges de personnel | B22: Charges de personnel
A23: Poste #N/A (non mappe GL) | B23: Charges de personnel | C23: traceur: complement exact des Charges de personnel P&L (4/5 entites)
A24: Pertes sur créances irrécouvrables | B24: Autres charges d'exploitation | C24: PCG: 654 -> Autres charges d'exploitation
A25: Autres charges de gestion courante | B25: Autres charges d'exploitation
A26: Charges financières | B26: Charges et produits financiers
A27: [obsolète] Charges financières | B27: Charges et produits financiers | C27: [obsolete] rattaché à sa nature
A28: [obsolète] Charges exceptionnelles | B28: Charges et produits exceptionnels | C28: [obsolete] rattaché à sa nature
A29: Dotations amort. & provisions | B29: Variations nettes des amortissements et des dépréciations
A30: Impôts sur les bénéfices & crédits d'impôt | B30: Impôt sur les bénéfices

Sheet GL_source
A1: Poste_GL | B1: H2R | C1: ALLIANCE | D1: BM EST | E1: KCOLD | F1: RIVAGROUPE | G1: VALPOLIS | H1: Ligne_PnL (VLOOKUP)
A2: Sous-traitance & prestations externes | B2: -275361 | C2: -48339 | D2: -463080 | E2: 0 | F2: -336289 | G2: -15029 | H2: =VLOOKUP(A2,Map_Postes!$A:$B,2,0)
A3: Fournitures & petit équipement | B3: 0 | C3: -857 | D3: -15587 | E3: 0 | F3: 0 | G3: 0 | H3: =VLOOKUP(A3,Map_Postes!$A:$B,2,0)
A4: Énergie, eau & carburants | B4: 0 | C4: -17254 | D4: -16293 | E4: 0 | F4: 0 | G4: 0 | H4: =VLOOKUP(A4,Map_Postes!$A:$B,2,0)
A5: Logiciels, IT & hébergement | B5: 0 | C5: -289536 | D5: -244796 | E5: 0 | F5: 0 | G5: -591 | H5: =VLOOKUP(A5,Map_Postes!$A:$B,2,0)
A6: Achats de marchandises | B6: 0 | C6: 0 | D6: -1298 | E6: 0 | F6: 0 | G6: 0 | H6: =VLOOKUP(A6,Map_Postes!$A:$B,2,0)
A7: Management fees / intra-groupe | B7: -1078798 | C7: -246503 | D7: -2884993 | E7: 0 | F7: 0 | G7: -104581 | H7: =VLOOKUP(A7,Map_Postes!$A:$B,2,0)
A8: Formation | B8: -166 | C8: -1279 | D8: -135743 | E8: 0 | F8: -925 | G8: -4297 | H8: =VLOOKUP(A8,Map_Postes!$A:$B,2,0)
A9: Recrutement | B9: 0 | C9: 0 | D9: -335279 | E9: 0 | F9: 0 | G9: 0 | H9: =VLOOKUP(A9,Map_Postes!$A:$B,2,0)
A10: Prestations conseillers TPE | B10: 0 | C10: 0 | D10: -136255 | E10: 0 | F10: 0 | G10: 0 | H10: =VLOOKUP(A10,Map_Postes!$A:$B,2,0)
A11: Locations & crédit-bail | B11: -10495 | C11: -34884 | D11: -155629 | E11: -600 | F11: -18157 | G11: -19360 | H11: =VLOOKUP(A11,Map_Postes!$A:$B,2,0)
A12: Entretien & maintenance | B12: -6000 | C12: -12591 | D12: -34692 | E12: 0 | F12: 0 | G12: -5846 | H12: =VLOOKUP(A12,Map_Postes!$A:$B,2,0)
A13: Assurances | B13: 0 | C13: -17136 | D13: -7872 | E13: 0 | F13: -6435 | G13: 0 | H13: =VLOOKUP(A13,Map_Postes!$A:$B,2,0)
... A30: Impôts sur les bénéfices & crédits d'impôt | B30: 0 | C30: -108381 | D30: 33039 | E30: 0 | F30: 1498 | G30: 3856 | H30: =VLOOKUP(A30,Map_Postes!$A:$B,2,0)
A31: Total (controle) | B31: =SUM(B2:B30) | C31: =SUM(C2:C30) | D31: =SUM(D2:D30) | E31: =SUM(E2:E30) | F31: =SUM(F2:F30) | G31: =SUM(G2:G30)

Sheet GL_retraite
A1: Ligne P&L | B1: SARL H2R | C1: SAS GROUPE RIVALIS | D1: SARL BM EST | E1: RIVAGROUPE SAS | F1: SARL VALPOLIS | G1: KCOLD (orphelin) | H1: Total conso (5 ent.)
A2: Achats consommés | B2: =SUMIF(GL_source!$H$2:$H$30,$A2,GL_source!$B$2:$B$30) | C2: =SUMIF(GL_source!$H$2:$H$30,$A2,GL_source!$C$2:$C$30) | D2: =SUMIF(GL_source!$H$2:$H$30,$A2,GL_source!$D$2:$D$30) | E2: =SUMIF(GL_source!$H$2:$H$30,$A2,GL_source!$F$2:$F$30) | F2: =SUMIF(GL_source!$H$2:$H$30,$A2,GL_source!$G$2:$G$30) | G2: =SUMIF(GL_source!$H$2:$H$30,$A2,GL_source!$E$2:$E$30) | H2: =SUM(B2:F2)
A3: Charges externes | B3: =SUMIF(GL_source!$H$2:$H$30,$A3,GL_source!$B$2:$B$30) | C3: =SUMIF(GL_source!$H$2:$H$30,$A3,GL_source!$C$2:$C$30) | D3: =SUMIF(GL_source!$H$2:$H$30,$A3,GL_source!$D$2:$D$30) | E3: =SUMIF(GL_source!$H$2:$H$30,$A3,GL_source!$F$2:$F$30) | F3: =SUMIF(GL_source!$H$2:$H$30,$A3,GL_source!$G$2:$G$30) | G3: =SUMIF(GL_source!$H$2:$H$30,$A3,GL_source!$E$2:$E$30) | H3: =SUM(B3:F3)
A4: Charges de personnel | B4: =SUMIF(GL_source!$H$2:$H$30,$A4,GL_source!$B$2:$B$30) | C4: =SUMIF(GL_source!$H$2:$H$30,$A4,GL_source!$C$2:$C$30) | D4: =SUMIF(GL_source!$H$2:$H$30,$A4,GL_source!$D$2:$D$30) | E4: =SUMIF(GL_source!$H$2:$H$30,$A4,GL_source!$F$2:$F$30) | F4: =SUMIF(GL_source!$H$2:$H$30,$A4,GL_source!$G$2:$G$30) | G4: =SUMIF(GL_source!$H$2:$H$30,$A4,GL_source!$E$2:$E$30) | H4: =SUM(B4:F4)
A5: Autres charges d'exploitation | B5: =SUMIF(GL_source!$H$2:$H$30,$A5,GL_source!$B$2:$B$30) | C5: =SUMIF(GL_source!$H$2:$H$30,$A5,GL_source!$C$2:$C$30) | D5: =SUMIF(GL_source!$H$2:$H$30,$A5,GL_source!$D$2:$D$30) | E5: =SUMIF(GL_source!$H$2:$H$30,$A5,GL_source!$F$2:$F$30) | F5: =SUMIF(GL_source!$H$2:$H$30,$A5,GL_source!$G$2:$G$30) | G5: =SUMIF(GL_source!$H$2:$H$30,$A5,GL_source!$E$2:$E$30) | H5: =SUM(B5:F5)
A6: Impôts et taxes | B6: =SUMIF(GL_source!$H$2:$H$30,$A6,GL_source!$B$2:$B$30) | C6: =SUMIF(GL_source!$H$2:$H$30,$A6,GL_source!$C$2:$C$30) | D6: =SUMIF(GL_source!$H$2:$H$30,$A6,GL_source!$D$2:$D$30) | E6: =SUMIF(GL_source!$H$2:$H$30,$A6,GL_source!$F$2:$F$30) | F6: =SUMIF(GL_source!$H$2:$H$30,$A6,GL_source!$G$2:$G$30) | G6: =SUMIF(GL_source!$H$2:$H$30,$A6,GL_source!$E$2:$E$30) | H6: =SUM(B6:F6)
A7: Variations nettes des amortissements et des dépréciations | B7: =SUMIF(GL_source!$H$2:$H$30,$A7,GL_source!$B$2:$B$30) | C7: =SUMIF(GL_source!$H$2:$H$30,$A7,GL_source!$C$2:$C$30) | D7: =SUMIF(GL_source!$H$2:$H$30,$A7,GL_source!$D$2:$D$30) | E7: =SUMIF(GL_source!$H$2:$H$30,$A7,GL_source!$F$2:$F$30) | F7: =SUMIF(GL_source!$H$2:$H$30,$A7,GL_source!$G$2:$G$30) | G7: =SUMIF(GL_source!$H$2:$H$30,$A7,GL_source!$E$2:$E$30) | H7: =SUM(B7:F7)
A8: Opérations d'exploitation Intra-Groupe | B8: =SUMIF(GL_source!$H$2:$H$30,$A8,GL_source!$B$2:$B$30) | C8: =SUMIF(GL_source!$H$2:$H$30,$A8,GL_source!$C$2:$C$30) | D8: =SUMIF(GL_source!$H$2:$H$30,$A8,GL_source!$D$2:$D$30) | E8: =SUMIF(GL_source!$H$2:$H$30,$A8,GL_source!$F$2:$F$30) | F8: =SUMIF(GL_source!$H$2:$H$30,$A8,GL_source!$G$2:$G$30) | G8: =SUMIF(GL_source!$H$2:$H$30,$A8,GL_source!$E$2:$E$30) | H8: =SUM(B8:F8)
A9: Charges et produits financiers | B9: =SUMIF(GL_source!$H$2:$H$30,$A9,GL_source!$B$2:$B$30) | C9: =SUMIF(GL_source!$H$2:$H$30,$A9,GL_source!$C$2:$C$30) | D9: =SUMIF(GL_source!$H$2:$H$30,$A9,GL_source!$D$2:$D$30) | E9: =SUMIF(GL_source!$H$2:$H$30,$A9,GL_source!$F$2:$F$30) | F9: =SUMIF(GL_source!$H$2:$H$30,$A9,GL_source!$G$2:$G$30) | G9: =SUMIF(GL_source!$H$2:$H$30,$A9,GL_source!$E$2:$E$30) | H9: =SUM(B9:F9)
A10: Opérations financières Intra-Groupe | B10: =SUMIF(GL_source!$H$2:$H$30,$A10,GL_source!$B$2:$B$30) | C10: =SUMIF(GL_source!$H$2:$H$30,$A10,GL_source!$C$2:$C$30) | D10: =SUMIF(GL_source!$H$2:$H$30,$A10,GL_source!$D$2:$D$30) | E10: =SUMIF(GL_source!$H$2:$H$30,$A10,GL_source!$F$2:$F$30) | F10: =SUMIF(GL_source!$H$2:$H$30,$A10,GL_source!$G$2:$G$30) | G10: =SUMIF(GL_source!$H$2:$H$30,$A10,GL_source!$E$2:$E$30) | H10: =SUM(B10:F10)
A11: Charges et produits exceptionnels | B11: =SUMIF(GL_source!$H$2:$H$30,$A11,GL_source!$B$2:$B$30) | C11: =SUMIF(GL_source!$H$2:$H$30,$A11,GL_source!$C$2:$C$30) | D11: =SUMIF(GL_source!$H$2:$H$30,$A11,GL_source!$D$2:$D$30) | E11: =SUMIF(GL_source!$H$2:$H$30,$A11,GL_source!$F$2:$F$30) | F11: =SUMIF(GL_source!$H$2:$H$30,$A11,GL_source!$G$2:$G$30) | G11: =SUMIF(GL_source!$H$2:$H$30,$A11,GL_source!$E$2:$E$30) | H11: =SUM(B11:F11)
A12: Opérations exceptionnelles Intra-Groupe | B12: =SUMIF(GL_source!$H$2:$H$30,$A12,GL_source!$B$2:$B$30) | C12: =SUMIF(GL_source!$H$2:$H$30,$A12,GL_source!$C$2:$C$30) | D12: =SUMIF(GL_source!$H$2:$H$30,$A12,GL_source!$D$2:$D$30) | E12: =SUMIF(GL_source!$H$2:$H$30,$A12,GL_source!$F$2:$F$30) | F12: =SUMIF(GL_source!$H$2:$H$30,$A12,GL_source!$G$2:$G$30) | G12: =SUMIF(GL_source!$H$2:$H$30,$A12,GL_source!$E$2:$E$30) | H12: =SUM(B12:F12)
A13: Impôt sur les bénéfices | B13: =SUMIF(GL_source!$H$2:$H$30,$A13,GL_source!$B$2:$B$30) | C13: =SUMIF(GL_source!$H$2:$H$30,$A13,GL_source!$C$2:$C$30) | D13: =SUMIF(GL_source!$H$2:$H$30,$A13,GL_source!$D$2:$D$30) | E13: =SUMIF(GL_source!$H$2:$H$30,$A13,GL_source!$F$2:$F$30) | F13: =SUMIF(GL_source!$H$2:$H$30,$A13,GL_source!$G$2:$G$30) | G13: =SUMIF(GL_source!$H$2:$H$30,$A13,GL_source!$E$2:$E$30) | H13: =SUM(B13:F13)
A14: TOTAL charges + IS | B14: =SUM(B2:B13) | C14: =SUM(C2:C13) | D14: =SUM(D2:D13) | E14: =SUM(E2:E13) | F14: =SUM(F2:F13) | G14: =SUM(G2:G13) | H14: =SUM(H2:H13)

Sheet PnL_cible
A1: Ligne P&L | B1: SARL H2R | C1: SAS GROUPE RIVALIS | D1: SARL BM EST | E1: RIVAGROUPE SAS | F1: SARL VALPOLIS | G1: Total
A2: Achats consommés | B2: -35405 | C2: -112295 | D2: -235384 | E2: -36 | F2: 0 | G2: =SUM(B2:F2)
A3: Charges externes | B3: -533656 | C3: -649779 | D3: -1684551 | E3: -66653 | F3: -133161 | G3: =SUM(B3:F3)
A4: Charges de personnel | B4: -35546 | C4: -238132 | D4: -2516306 | E4: -221792 | F4: -359684 | G4: =SUM(B4:F4)
A5: Autres charges d'exploitation | B5: -11 | C5: -1 | D5: -1007517 | E5: -12 | F5: -1576 | G5: =SUM(B5:F5)
A6: Impôts et taxes | B6: -942 | C6: -13021 | D6: -36605 | E6: -16565 | F6: -7909 | G6: =SUM(B6:F6)
A7: Variations nettes des amortissements et des dépréciations | B7: 0 | C7: -748024 | D7: -627271 | E7: -9345 | F7: -7839 | G7: =SUM(B7:F7)
A8: Opérations d'exploitation Intra-Groupe | B8: -1061813 | C8: 2646979 | D8: -2333944 | E8: 258091 | F8: 490687 | G8: =SUM(B8:F8)
A9: Charges et produits financiers | B9: 80 | C9: -30694 | D9: -48002 | E9: 458 | F9: -954 | G9: =SUM(B9:F9)
A10: Opérations financières Intra-Groupe | B10: 3287 | C10: 17851 | D10: 4233 | E10: -28023 | F10: 2652 | G10: =SUM(B10:F10)
A11: Charges et produits exceptionnels | B11: 0 | C11: 0 | D11: -58332 | E11: 0 | F11: 23 | G11: =SUM(B11:F11)
A12: Opérations exceptionnelles Intra-Groupe | B12: 0 | C12: 0 | D12: 0 | E12: 0 | F12: 0 | G12: =SUM(B12:F12)
A13: Impôt sur les bénéfices | B13: 0 | C13: -49743 | D13: 77375 | E13: 1498 | F13: 3856 | G13: =SUM(B13:F13)
A15: INFO (produits - hors bridge charges, le GL n'a pas de CA) :
A16: Chiffre d'affaires | B16: 1682762 | C16: 1 | D16: 8759010 | E16: 8320 | F16: 5699
A17: Autres produits d'exploitation | B17: 0 | C17: 1926 | D17: 42071 | E17: 1469 | F17: 2950

Sheet Bridge_entite
A1: Entité P&L | B1: Ligne P&L | C1: GL recalculé | D1: P&L cible | E1: Écart € | F1: Écart %
A2: SARL H2R | B2: Achats consommés | C2: =GL_retraite!B2 | D2: =PnL_cible!B2 | E2: =C2-D2 | F2: =IF(D2=0,"",E2/D2)
A3: SARL H2R | B3: Charges externes | C3: =GL_retraite!B3 | D3: =PnL_cible!B3 | E3: =C3-D3 | F3: =IF(D3=0,"",E3/D3)
A4: SARL H2R | B4: Charges de personnel | C4: =GL_retraite!B4 | D4: =PnL_cible!B4 | E4: =C4-D4 | F4: =IF(D4=0,"",E4/D4)
A5: SARL H2R | B5: Autres charges d'exploitation | C5: =GL_retraite!B5 | D5: =PnL_cible!B5 | E5: =C5-D5 | F5: =IF(D5=0,"",E5/D5)
A6: SARL H2R | B6: Impôts et taxes | C6: =GL_retraite!B6 | D6: =PnL_cible!B6 | E6: =C6-D6 | F6: =IF(D6=0,"",E6/D6)
A7: SARL H2R | B7: Variations nettes des amortissements et des dépréciations | C7: =GL_retraite!B7 | D7: =PnL_cible!B7 | E7: =C7-D7 | F7: =IF(D7=0,"",E7/D7)
A8: SARL H2R | B8: Opérations d'exploitation Intra-Groupe | C8: =GL_retraite!B8 | D8: =PnL_cible!B8 | E8: =C8-D8 | F8: =IF(D8=0,"",E8/D8)
A9: SARL H2R | B9: Charges et produits financiers | C9: =GL_retraite!B9 | D9: =PnL_cible!B9 | E9: =C9-D9 | F9: =IF(D9=0,"",E9/D9)
A10: SARL H2R | B10: Opérations financières Intra-Groupe | C10: =GL_retraite!B10 | D10: =PnL_cible!B10 | E10: =C10-D10 | F10: =IF(D10=0,"",E10/D10)
A11: SARL H2R | B11: Charges et produits exceptionnels | C11: =GL_retraite!B11 | D11: =PnL_cible!B11 | E11: =C11-D11 | F11: =IF(D11=0,"",E11/D11)
A12: SARL H2R | B12: Opérations exceptionnelles Intra-Groupe | C12: =GL_retraite!B12 | D12: =PnL_cible!B12 | E12: =C12-D12 | F12: =IF(D12=0,"",E12/D12)
A13: SARL H2R | B13: Impôt sur les bénéfices | C13: =GL_retraite!B13 | D13: =PnL_cible!B13 | E13: =C13-D13 | F13: =IF(D13=0,"",E13/D13)
A14: SAS GROUPE RIVALIS | B14: Achats consommés | C14: =GL_retraite!C2 | D14: =PnL_cible!C2 | E14: =C14-D14 | F14: =IF(D14=0,"",E14/D14)
A15: SAS GROUPE RIVALIS | B15: Charges externes | C15: =GL_retraite!C3 | D15: =PnL_cible!C3 | E15: =C15-D15 | F15: =IF(D15=0,"",E15/D15)
A16: SAS GROUPE RIVALIS | B16: Charges de personnel | C16: =GL_retraite!C4 | D16: =PnL_cible!C4 | E16: =C16-D16 | F16: =IF(D16=0,"",E16/D16)
A17: SAS GROUPE RIVALIS | B17: Autres charges d'exploitation | C17: =GL_retraite!C5 | D17: =PnL_cible!C5 | E17: =C17-D17 | F17: =IF(D17=0,"",E17/D17)
A18: SAS GROUPE RIVALIS | B18: Impôts et taxes | C18: =GL_retraite!C6 | D18: =PnL_cible!C6 | E18: =C18-D18 | F18: =IF(D18=0,"",E18/D18)
A19: SAS GROUPE RIVALIS | B19: Variations nettes des amortissements et des dépréciations | C19: =GL_retraite!C7 | D19: =PnL_cible!C7 | E19: =C19-D19 | F19: =IF(D19=0,"",E19/D19)
A20: SAS GROUPE RIVALIS | B20: Opérations d'exploitation Intra-Groupe | C20: =GL_retraite!C8 | D20: =PnL_cible!C8 | E20: =C20-D20 | F20: =IF(D20=0,"",E20/D20)
A21: SAS GROUPE RIVALIS | B21: Charges et produits financiers | C21: =GL_retraite!C9 | D21: =PnL_cible!C9 | E21: =C21-D21 | F21: =IF(D21=0,"",E21/D21)
A22: SAS GROUPE RIVALIS | B22: Opérations financières Intra-Groupe | C22: =GL_retraite!C10 | D22: =PnL_cible!C10 | E22: =C22-D22 | F22: =IF(D22=0,"",E22/D22)
A23: SAS GROUPE RIVALIS | B23: Charges et produits exceptionnels | C23: =GL_retraite!C11 | D23: =PnL_cible!C11 | E23: =C23-D23 | F23: =IF(D23=0,"",E23/D23)
A24: SAS GROUPE RIVALIS | B24: Opérations exceptionnelles Intra-Groupe | C24: =GL_retraite!C12 | D24: =PnL_cible!C12 | E24: =C24-D24 | F24: =IF(D24=0,"",E24/D24)
A25: SAS GROUPE RIVALIS | B25: Impôt sur les bénéfices | C25: =GL_retraite!C13 | D25: =PnL_cible!C13 | E25: =C25-D25 | F25: =IF(D25=0,"",E25/D25)
A26: SARL BM EST | B26: Achats consommés | C26: =GL_retraite!D2 | D26: =PnL_cible!D2 | E26: =C26-D26 | F26: =IF(D26=0,"",E26/D26)
A27: SARL BM EST | B27: Charges externes | C27: =GL_retraite!D3 | D27: =PnL_cible!D3 | E27: =C27-D27 | F27: =IF(D27=0,"",E27/D27)
A28: SARL BM EST | B28: Charges de personnel | C28: =GL_retraite!D4 | D28: =PnL_cible!D4 | E28: =C28-D28 | F28: =IF(D28=0,"",E28/D28)
A29: SARL BM EST | B29: Autres charges d'exploitation | C29: =GL_retraite!D5 | D29: =PnL_cible!D5 | E29: =C29-D29 | F29: =IF(D29=0,"",E29/D29)
A30: SARL BM EST | B30: Impôts et taxes | C30: =GL_retraite!D6 | D30: =PnL_cible!D6 | E30: =C30-D30 | F30: =IF(D30=0,"",E30/D30)
A31: SARL BM EST | B31: Variations nettes des amortissements et des dépréciations | C31: =GL_retraite!D7 | D31: =PnL_cible!D7 | E31: =C31-D31 | F31: =IF(D31=0,"",E31/D31)
A32: SARL BM EST | B32: Opérations d'exploitation Intra-Groupe | C32: =GL_retraite!D8 | D32: =PnL_cible!D8 | E32: =C32-D32 | F32: =IF(D32=0,"",E32/D32)
A33: SARL BM EST | B33: Charges et produits financiers | C33: =GL_retraite!D9 | D33: =PnL_cible!D9 | E33: =C33-D33 | F33: =IF(D33=0,"",E33/D33)
A34: SARL BM EST | B34: Opérations financières Intra-Groupe | C34: =GL_retraite!D10 | D34: =PnL_cible!D10 | E34: =C34-D34 | F34: =IF(D34=0,"",E34/D34)
A35: SARL BM EST | B35: Charges et produits exceptionnels | C35: =GL_retraite!D11 | D35: =PnL_cible!D11 | E35: =C35-D35 | F35: =IF(D35=0,"",E35/D35)
A36: SARL BM EST | B36: Opérations exceptionnelles Intra-Groupe | C36: =GL_retraite!D12 | D36: =PnL_cible!D12 | E36: =C36-D36 | F36: =IF(D36=0,"",E36/D36)
A37: SARL BM EST | B37: Impôt sur les bénéfices | C37: =GL_retraite!D13 | D37: =PnL_cible!D13 | E37: =C37-D37 | F37: =IF(D37=0,"",E37/D37)
A38: RIVAGROUPE SAS | B38: Achats consommés | C38: =GL_retraite!E2 | D38: =PnL_cible!E2 | E38: =C38-D38 | F38: =IF(D38=0,"",E38/D38)
A39: RIVAGROUPE SAS | B39: Charges externes | C39: =GL_retraite!E3 | D39: =PnL_cible!E3 | E39: =C39-D39 | F39: =IF(D39=0,"",E39/D39)
A40: RIVAGROUPE SAS | B40: Charges de personnel | C40: =GL_retraite!E4 | D40: =PnL_cible!E4 | E40: =C40-D40 | F40: =IF(D40=0,"",E40/D40)
...

Sheet Bridge_conso
A1: Ligne P&L | B1: GL recalculé | C1: P&L cible | D1: Écart € | E1: Écart % | F1: Type d'écart
A2: Achats consommés | B2: =GL_retraite!H2 | C2: =PnL_cible!G2 | D2: =B2-C2 | E2: =IF(C2=0,"",D2/C2) | F2: DONNEES: reclassement par destination (P&L inclut des achats/sous-traitance non identifiables en nature dans le GL)
A3: Charges externes | B3: =GL_retraite!H3 | C3: =PnL_cible!G3 | D3: =B3-C3 | E3: =IF(C3=0,"",D3/C3) | F3: DONNEES: la nature 'charges externes' du GL > P&L par destination (reclassements + conso)
A4: Charges de personnel | B4: =GL_retraite!H4 | C4: =PnL_cible!G4 | D4: =B4-C4 | E4: =IF(C4=0,"",D4/C4) | F4: MAPPING ok (incl. #N/A). Residuel = ALLIANCE/GROUPE RIVALIS (-10 534, ecart de source)
A5: Autres charges d'exploitation | B5: =GL_retraite!H5 | C5: =PnL_cible!G5 | D5: =B5-C5 | E5: =IF(C5=0,"",D5/C5) | F5: MAPPING ok (ecart ~0)
A6: Impôts et taxes | B6: =GL_retraite!H6 | C6: =PnL_cible!G6 | D6: =B6-C6 | E6: =IF(C6=0,"",D6/C6) | F6: DONNEES: perimetre/reclassement partiel
A7: Variations nettes des amortissements et des dépréciations | B7: =GL_retraite!H7 | C7: =PnL_cible!G7 | D7: =B7-C7 | E7: =IF(C7=0,"",D7/C7) | F7: DONNEES: dotations GL > P&L (retraitements de consolidation, ecarts d'acquisition)
A8: Opérations d'exploitation Intra-Groupe | B8: =GL_retraite!H8 | C8: =PnL_cible!G8 | D8: =B8-C8 | E8: =IF(C8=0,"",D8/C8) | F8: ELIMINATION: GL = charge intra -4 314 875; P&L net a 0 (jambe produit absente du GL)
A9: Charges et produits financiers | B9: =GL_retraite!H9 | C9: =PnL_cible!G9 | D9: =B9-C9 | E9: =IF(C9=0,"",D9/C9) | F9: DONNEES: charges fin. GL > P&L (reclassement / conso)
A10: Opérations financières Intra-Groupe | B10: =GL_retraite!H10 | C10: =PnL_cible!G10 | D10: =B10-C10 | E10: =IF(C10=0,"",D10/C10) | F10: Pas de detail intra-groupe financier dans le GL (P&L net a 0)
A11: Charges et produits exceptionnels | B11: =GL_retraite!H11 | C11: =PnL_cible!G11 | D11: =B11-C11 | E11: =IF(C11=0,"",D11/C11) | F11: MAPPING ok ([obsolete] rattache); faible ecart
A12: Opérations exceptionnelles Intra-Groupe | B12: =GL_retraite!H12 | C12: =PnL_cible!G12 | D12: =B12-C12 | E12: =IF(C12=0,"",D12/C12) | F12: Aucun poste GL (P&L = 0)
A13: Impôt sur les bénéfices | B13: =GL_retraite!H13 | C13: =PnL_cible!G13 | D13: =B13-C13 | E13: =IF(C13=0,"",D13/C13) | F13: DONNEES: IS GL vs P&L (signe/credits d'impot, retraitement)
A14: TOTAL charges + IS | B14: =SUM(B2:B13) | C14: =SUM(C2:C13) | D14: =SUM(D2:D13)
A16: CONTROLES
A17: GL retraite total 5 entites (conso) | B17: =B14
A18: KCOLD orphelin (isole, hors conso) | B18: =GL_retraite!G14
A19: P&L cible total charges + IS | B19: =C14
A20: Ecart total GL vs P&L | B20: =D14
A21: dont elimination intra-groupe (op. expl. intra) | B21: =D8
A22: Consolide GL annonce (CSV) - NON reconcilie | B22: -6191160

Sheet Ecarts
A1: Ligne P&L (conso) | B1: Écart € | C1: Écart % | D1: Catégorie | E1: Explication
A2: Opérations d'exploitation Intra-Groupe | B2: -4314875 | C2: 0 | D2: ELIMINATION | E2: ELIMINATION: GL = charge intra -4 314 875; P&L net a 0 (jambe produit absente du GL)
A3: Charges externes | B3: -1967146 | C3: 0.64122368 | D3: DONNEES | E3: DONNEES: la nature 'charges externes' du GL > P&L par destination (reclassements + conso)
A4: Variations nettes des amortissements et des dépréciations | B4: -1679382 | C4: 1.2060376 | D4: DONNEES | E4: DONNEES: dotations GL > P&L (retraitements de consolidation, ecarts d'acquisition)
A5: Achats consommés | B5: 331831 | C5: -0.86612811 | D5: DONNEES | E5: DONNEES: reclassement par destination (P&L inclut des achats/sous-traitance non identifiables en nature dans le GL)
A6: Charges et produits financiers | B6: -295253 | C6: 3.7320887 | D6: DONNEES | E6: DONNEES: charges fin. GL > P&L (reclassement / conso)
A7: Impôt sur les bénéfices | B7: -102974 | C7: -3.1217486 | D7: DONNEES | E7: DONNEES: IS GL vs P&L (signe/credits d'impot, retraitement)
A8: Impôts et taxes | B8: 31307 | C8: -0.41719304 | D8: DONNEES | E8: DONNEES: perimetre/reclassement partiel
A9: Charges de personnel | B9: -10533 | C9: 0.0031241658 | D9: MAPPING | E9: MAPPING ok (incl. #N/A). Residuel = ALLIANCE/GROUPE RIVALIS (-10 534, ecart de source)
